Workbook

Sheet Overview
B2: Project overview
B3: A six-month revenue forecast and media-mix model I built for a single-product consumer hardware brand. The product is a small device that helps people break phone-addiction habits by locking distracting apps. Average order value is about $65. The brand sells direct to consumer through its own store and, since March 2026, on Amazon, with paid media running across Meta, Google, TikTok, and Amazon.
B7: The Monthly Data tab holds 12 months of channel performance (July 2025 to June 2026). Unit economics, the seasonality/promo calendar, and a data dictionary sit on their own tabs.
B11: What the model does
B12: 1. Forecast and levers
B13: Projects H2 2026 revenue against a target of +20% growth over the trailing six months (January to June 2026), with core assumptions stated explicitly. It also quantifies which lever moves revenue more: a five-point shift in conversion rate, or a 10% increase in spend, showing the elasticity behind that comparison.
B17: 2. The strategic call
B18: Flags the channel that's underperforming relative to its potential and recommends whether to optimize, pause, or scale it, backed by the data. The decision is framed around contribution margin, not just MER or ROAS.
B22: 3. Pressure test
B23: Models about 15% media inflation next quarter and shows how to adjust the media mix to hold a blended MER at or below 35% without giving up total revenue, including the trade-offs involved.
B27: Approach
B28: Built for transparency: every blue cell is an editable input, every black cell is a calculation, and green cells link to another tab. Assumptions are stated up front, and sensitivity/elasticity thinking runs through the levers section so the reasoning is visible rather than a single black-box number.
B32: Note: MER is defined as marketing spend divided by revenue (lower is better). Assumptions are called out inline where I had to make a judgment call or fill a gap in the data.

Sheet Assumptions
A1: H2 2026 Forecast: Key Assumptions & Drivers
A2: Blue = editable input. Black = formula/calculation. Green = link to another tab. Adjust the blue cells to test different scenarios; everything downstream recalculates.
A4: Unit Economics (Pulled from Unit Economics & Calendar)
A5: Average order value (AOV, $) | B5: ='Unit Economics & Calendar'!C3 -> 65
A6: Gross margin % | B6: ='Unit Economics & Calendar'!C4 -> 0.6
A7: Amazon marketplace fee % | B7: ='Unit Economics & Calendar'!C6 -> 0.15
A8: DTC gross profit per unit ($) | B8: ='Unit Economics & Calendar'!C7 -> 39
A9: Amazon gross profit per unit ($) | B9: ='Unit Economics & Calendar'!C8 -> 29.25
A11: Trailing 6-Month Actuals (Jan-Jun 2026) & Growth Target
A12: Trailing 6mo total spend ($) | B12: =SUM('Blended Summary'!B8:B13) -> 3950800
A13: Trailing 6mo total conversions | B13: =SUM('Blended Summary'!C8:C13) -> 171000
A14: Trailing 6mo total revenue ($) | B14: =SUM('Blended Summary'!D8:D13) -> 11115000
A15: Trailing 6mo Amazon revenue ($) | B15: =SUM('Monthly Data'!K2:K5) -> 1137500 | C15: Amazon only has data for Mar-Jun '26, fully inside the trailing window
A16: Trailing 6mo core (Meta+Google+TikTok) revenue ($) | B16: =B14-B15 -> 9977500
A17: Trailing avg season index (Jan-Jun) | B17: =AVERAGE('Blended Summary'!H8:H13) -> 1.0166667
A18: Target revenue growth, H2 vs trailing 6mo | B18: 0.2
A19: Target H2 2026 revenue ($) | B19: =B14*(1+B18) -> 13338000
A21: H2 2026 Seasonality — Assumed to Repeat the Jul-Dec 2025 Pattern (Only Year of Data We Have)
A22: Jul 2026 season index | B22: ='Unit Economics & Calendar'!C15 -> 0.85
A23: Aug 2026 season index | B23: ='Unit Economics & Calendar'!C16 -> 0.9
A24: Sep 2026 season index | B24: ='Unit Economics & Calendar'!C17 -> 0.95
A25: Oct 2026 season index | B25: ='Unit Economics & Calendar'!C18 -> 1.05
A26: Nov 2026 (BFCM) season index | B26: ='Unit Economics & Calendar'!C19 -> 1.5
A27: Dec 2026 (Holiday) season index | B27: ='Unit Economics & Calendar'!C20 -> 1.7
A28: Forecast avg season index (Jul-Dec) | B28: =AVERAGE(B22:B27) -> 1.1583333
A30: Channel Strategy Levers (H2 Forecast Inputs)
A31: Channel | B31: Spend multiplier vs June run-rate | C31: CAC trend adjustment % | D31: Strategic note
A32: Meta | B32: 1 | C32: 0 | D32: Optimize: cap spend growth to seasonal pace only, push CAC efficiency before adding budget.
A33: Google | B33: 1.15 | C33: 0 | D33: Primary scaling destination; highest contribution/unit ($22) in the mix. Growth capped by demand ceiling, so monitor CPAs closely.
A34: TikTok | B34: 1.1 | C34: 0.08 | D34: Scale modestly; improving CAC trend supports higher spend, but hold back from aggressive scaling during an inflation quarter.
A35: Amazon | B35: 1 | C35: 0 | D35: Continue the ramp; BFCM/Holiday seasonality for this channel is genuinely unknown -- biggest assumption in this model.
A37: Lever Sensitivity Inputs (Spend vs. CVR Lever)
A38: Lever A: spend increase % | B38: 0.1
A39: Lever B1: literal blended CVR shift (points) | B39: 0.05 | C39: Taking "five points" literally at the blended level. Shown to demonstrate why this unit breaks down.
A40: Lever B2: realistic blended CVR shift (points) | B40: 0.005 | C40: A more achievable 0.5pp improvement. The fair comparison to Lever A.
A42: Pressure Test Inputs (Media Inflation)
A43: Media inflation assumption, next quarter | B43: 0.15
A44: Target blended MER ceiling | B44: 0.35

Sheet H2 2026 Forecast
A1: H2 2026 (Jul-Dec) Forecast by Channel
A2: Drives off the Assumptions tab. Edit the spend multipliers / CAC adjustments there to test alternative forecasts here.
B4: Jul 2026 | C4: Aug 2026 | D4: Sep 2026 | E4: Oct 2026 | F4: Nov 2026 | G4: Dec 2026 | H4: H2 2026 Total
A5: Month # | B5: 13 | C5: 14 | D5: 15 | E5: 16 | F5: 17 | G5: 18
A7: Meta
A8: Season index | B8: =Assumptions!B22 -> 0.85 | C8: =Assumptions!B23 -> 0.9 | D8: =Assumptions!B24 -> 0.95 | E8: =Assumptions!B25 -> 1.05 | F8: =Assumptions!B26 -> 1.5 | G8: =Assumptions!B27 -> 1.7
A9: Spend ($) | B9: ='Monthly Data'!$F$29*Assumptions!$B$32*(B8/'Blended Summary'!$H$13) -> 374755.56 | C9: ='Monthly Data'!$F$29*Assumptions!$B$32*(C8/'Blended Summary'!$H$13) -> 396800 | D9: ='Monthly Data'!$F$29*Assumptions!$B$32*(D8/'Blended Summary'!$H$13) -> 418844.44 | E9: ='Monthly Data'!$F$29*Assumptions!$B$32*(E8/'Blended Summary'!$H$13) -> 462933.33 | F9: ='Monthly Data'!$F$29*Assumptions!$B$32*(F8/'Blended Summary'!$H$13) -> 661333.33 | G9: ='Monthly Data'!$F$29*Assumptions!$B$32*(G8/'Blended Summary'!$H$13) -> 749511.11 | H9: =SUM(B9:G9) -> 3064177.8
A10: Projected CAC ($) | B10: {=TREND('Monthly Data'!$J$18:$J$29,'Monthly Data'!$B$18:$B$29,B5)*(1+Assumptions!$C$32)} -> 31.015152 | C10: {=TREND('Monthly Data'!$J$18:$J$29,'Monthly Data'!$B$18:$B$29,C5)*(1+Assumptions!$C$32)} -> 31.812354 | D10: {=TREND('Monthly Data'!$J$18:$J$29,'Monthly Data'!$B$18:$B$29,D5)*(1+Assumptions!$C$32)} -> 32.609557 | E10: {=TREND('Monthly Data'!$J$18:$J$29,'Monthly Data'!$B$18:$B$29,E5)*(1+Assumptions!$C$32)} -> 33.40676 | F10: {=TREND('Monthly Data'!$J$18:$J$29,'Monthly Data'!$B$18:$B$29,F5)*(1+Assumptions!$C$32)} -> 34.203963 | G10: {=TREND('Monthly Data'!$J$18:$J$29,'Monthly Data'!$B$18:$B$29,G5)*(1+Assumptions!$C$32)} -> 35.001165 | H10: =H9/H11 -> 33.303853
A11: Conversions | B11: =B9/B10 -> 12082.983 | C11: =C9/C10 -> 12473.142 | D11: =D9/D10 -> 12844.224 | E11: =E9/E10 -> 13857.475 | F11: =F9/F10 -> 19334.992 | G11: =G9/G10 -> 21413.89 | H11: =SUM(B11:G11) -> 92006.705
A12: Revenue ($) | B12: =B11*Assumptions!$B$5 -> 785393.91 | C12: =C11*Assumptions!$B$5 -> 810754.2 | D12: =D11*Assumptions!$B$5 -> 834874.54 | E12: =E11*Assumptions!$B$5 -> 900735.86 | F12: =F11*Assumptions!$B$5 -> 1256774.5 | G12: =G11*Assumptions!$B$5 -> 1391902.9 | H12: =SUM(B12:G12) -> 5980435.8
A13: Contribution / unit ($) | B13: =Assumptions!$B$8-B10 -> 7.9848485 | C13: =Assumptions!$B$8-C10 -> 7.1876457 | D13: =Assumptions!$B$8-D10 -> 6.3904429 | E13: =Assumptions!$B$8-E10 -> 5.5932401 | F13: =Assumptions!$B$8-F10 -> 4.7960373 | G13: =Assumptions!$B$8-G10 -> 3.9988345
A14: Total contribution ($) | B14: =B13*B11 -> 96480.79 | C14: =C13*C11 -> 89652.522 | D14: =D13*D11 -> 82080.278 | E14: =E13*E11 -> 77508.184 | F14: =F13*F11 -> 92731.341 | G14: =G13*G11 -> 85630.602 | H14: =SUM(B14:G14) -> 524083.72
A16: Google
A17: Season index | B17: =Assumptions!B22 -> 0.85 | C17: =Assumptions!B23 -> 0.9 | D17: =Assumptions!B24 -> 0.95 | E17: =Assumptions!B25 -> 1.05 | F17: =Assumptions!B26 -> 1.5 | G17: =Assumptions!B27 -> 1.7
A18: Spend ($) | B18: ='Monthly Data'!$F$17*Assumptions!$B$33*(B17/'Blended Summary'!$H$13) -> 158789.44 | C18: ='Monthly Data'!$F$17*Assumptions!$B$33*(C17/'Blended Summary'!$H$13) -> 168130 | D18: ='Monthly Data'!$F$17*Assumptions!$B$33*(D17/'Blended Summary'!$H$13) -> 177470.56 | E18: ='Monthly Data'!$F$17*Assumptions!$B$33*(E17/'Blended Summary'!$H$13) -> 196151.67 | F18: ='Monthly Data'!$F$17*Assumptions!$B$33*(F17/'Blended Summary'!$H$13) -> 280216.67 | G18: ='Monthly Data'!$F$17*Assumptions!$B$33*(G17/'Blended Summary'!$H$13) -> 317578.89 | H18: =SUM(B18:G18) -> 1298337.2
A19: Projected CAC ($) | B19: {=TREND('Monthly Data'!$J$6:$J$17,'Monthly Data'!$B$6:$B$17,B5)*(1+Assumptions!$C$33)} -> 16.318182 | C19: {=TREND('Monthly Data'!$J$6:$J$17,'Monthly Data'!$B$6:$B$17,C5)*(1+Assumptions!$C$33)} -> 16.636364 | D19: {=TREND('Monthly Data'!$J$6:$J$17,'Monthly Data'!$B$6:$B$17,D5)*(1+Assumptions!$C$33)} -> 16.954545 | E19: {=TREND('Monthly Data'!$J$6:$J$17,'Monthly Data'!$B$6:$B$17,E5)*(1+Assumptions!$C$33)} -> 17.272727 | F19: {=TREND('Monthly Data'!$J$6:$J$17,'Monthly Data'!$B$6:$B$17,F5)*(1+Assumptions!$C$33)} -> 17.590909 | G19: {=TREND('Monthly Data'!$J$6:$J$17,'Monthly Data'!$B$6:$B$17,G5)*(1+Assumptions!$C$33)} -> 17.909091 | H19: =H18/H20 -> 17.236919
A20: Conversions | B20: =B18/B19 -> 9730.8295 | C20: =C18/C19 -> 10106.175 | D20: =D18/D19 -> 10467.432 | E20: =E18/E19 -> 11356.149 | F20: =F18/F19 -> 15929.63 | G20: =G18/G19 -> 17732.831 | H20: =SUM(B20:G20) -> 75323.047
A21: Revenue ($) | B21: =B20*Assumptions!$B$5 -> 632503.92 | C21: =C20*Assumptions!$B$5 -> 656901.37 | D21: =D20*Assumptions!$B$5 -> 680383.09 | E21: =E20*Assumptions!$B$5 -> 738149.69 | F21: =F20*Assumptions!$B$5 -> 1035425.9 | G21: =G20*Assumptions!$B$5 -> 1152634 | H21: =SUM(B21:G21) -> 4895998
A22: Contribution / unit ($) | B22: =Assumptions!$B$8-B19 -> 22.681818 | C22: =Assumptions!$B$8-C19 -> 22.363636 | D22: =Assumptions!$B$8-D19 -> 22.045455 | E22: =Assumptions!$B$8-E19 -> 21.727273 | F22: =Assumptions!$B$8-F19 -> 21.409091 | G22: =Assumptions!$B$8-G19 -> 21.090909
A23: Total contribution ($) | B23: =B22*B20 -> 220712.9 | C23: =C22*C20 -> 226010.82 | D23: =D22*D20 -> 230759.3 | E23: =E22*E20 -> 246738.15 | F23: =F22*F20 -> 341038.89 | G23: =G22*G20 -> 374001.53 | H23: =SUM(B23:G23) -> 1639261.6
A25: TikTok
A26: Season index | B26: =Assumptions!B22 -> 0.85 | C26: =Assumptions!B23 -> 0.9 | D26: =Assumptions!B24 -> 0.95 | E26: =Assumptions!B25 -> 1.05 | F26: =Assumptions!B26 -> 1.5 | G26: =Assumptions!B27 -> 1.7
A27: Spend ($) | B27: ='Monthly Data'!$F$41*Assumptions!$B$34*(B26/'Blended Summary'!$H$13) -> 55372.778 | C27: ='Monthly Data'!$F$41*Assumptions!$B$34*(C26/'Blended Summary'!$H$13) -> 58630 | D27: ='Monthly Data'!$F$41*Assumptions!$B$34*(D26/'Blended Summary'!$H$13) -> 61887.222 | E27: ='Monthly Data'!$F$41*Assumptions!$B$34*(E26/'Blended Summary'!$H$13) -> 68401.667 | F27: ='Monthly Data'!$F$41*Assumptions!$B$34*(F26/'Blended Summary'!$H$13) -> 97716.667 | G27: ='Monthly Data'!$F$41*Assumptions!$B$34*(G26/'Blended Summary'!$H$13) -> 110745.56 | H27: =SUM(B27:G27) -> 452753.89
A28: Projected CAC ($) | B28: {=TREND('Monthly Data'!$J$30:$J$41,'Monthly Data'!$B$30:$B$41,B5)*(1+Assumptions!$C$34)} -> 25.101818 | C28: {=TREND('Monthly Data'!$J$30:$J$41,'Monthly Data'!$B$30:$B$41,C5)*(1+Assumptions!$C$34)} -> 23.342098 | D28: {=TREND('Monthly Data'!$J$30:$J$41,'Monthly Data'!$B$30:$B$41,D5)*(1+Assumptions!$C$34)} -> 21.582378 | E28: {=TREND('Monthly Data'!$J$30:$J$41,'Monthly Data'!$B$30:$B$41,E5)*(1+Assumptions!$C$34)} -> 19.822657 | F28: {=TREND('Monthly Data'!$J$30:$J$41,'Monthly Data'!$B$30:$B$41,F5)*(1+Assumptions!$C$34)} -> 18.062937 | G28: {=TREND('Monthly Data'!$J$30:$J$41,'Monthly Data'!$B$30:$B$41,G5)*(1+Assumptions!$C$34)} -> 16.303217 | H28: =H27/H29 -> 19.482905
A29: Conversions | B29: =B27/B28 -> 2205.927 | C29: =C27/C28 -> 2511.7708 | D29: =D27/D28 -> 2867.4886 | E29: =E27/E28 -> 3450.681 | F29: =F27/F28 -> 5409.7884 | G29: =G27/G28 -> 6792.8653 | H29: =SUM(B29:G29) -> 23238.521
A30: Revenue ($) | B30: =B29*Assumptions!$B$5 -> 143385.25 | C30: =C29*Assumptions!$B$5 -> 163265.1 | D30: =D29*Assumptions!$B$5 -> 186386.76 | E30: =E29*Assumptions!$B$5 -> 224294.26 | F30: =F29*Assumptions!$B$5 -> 351636.24 | G30: =G29*Assumptions!$B$5 -> 441536.24 | H30: =SUM(B30:G30) -> 1510503.9
A31: Contribution / unit ($) | B31: =Assumptions!$B$8-B28 -> 13.898182 | C31: =Assumptions!$B$8-C28 -> 15.657902 | D31: =Assumptions!$B$8-D28 -> 17.417622 | E31: =Assumptions!$B$8-E28 -> 19.177343 | F31: =Assumptions!$B$8-F28 -> 20.937063 | G31: =Assumptions!$B$8-G28 -> 22.696783
A32: Total contribution ($) | B32: =B31*B29 -> 30658.374 | C32: =C31*C29 -> 39329.061 | D32: =D31*D29 -> 49944.834 | E32: =E31*E29 -> 66174.892 | F32: =F31*F29 -> 113265.08 | G32: =G31*G29 -> 154176.19 | H32: =SUM(B32:G32) -> 453548.43
A34: Amazon
A35: Season index | B35: =Assumptions!B22 -> 0.85 | C35: =Assumptions!B23 -> 0.9 | D35: =Assumptions!B24 -> 0.95 | E35: =Assumptions!B25 -> 1.05 | F35: =Assumptions!B26 -> 1.5 | G35: =Assumptions!B27 -> 1.7
A36: Spend ($) | B36: ='Monthly Data'!$F$5*Assumptions!$B$35*(B35/'Blended Summary'!$H$13) -> 96333.333 | C36: ='Monthly Data'!$F$5*Assumptions!$B$35*(C35/'Blended Summary'!$H$13) -> 102000 | D36: ='Monthly Data'!$F$5*Assumptions!$B$35*(D35/'Blended Summary'!$H$13) -> 107666.67 | E36: ='Monthly Data'!$F$5*Assumptions!$B$35*(E35/'Blended Summary'!$H$13) -> 119000 | F36: ='Monthly Data'!$F$5*Assumptions!$B$35*(F35/'Blended Summary'!$H$13) -> 170000 | G36: ='Monthly Data'!$F$5*Assumptions!$B$35*(G35/'Blended Summary'!$H$13) -> 192666.67 | H36: =SUM(B36:G36) -> 787666.67
A37: Projected CAC ($) | B37: ='Monthly Data'!$J$5*(1+Assumptions!$C$35) -> 17 | C37: ='Monthly Data'!$J$5*(1+Assumptions!$C$35) -> 17 | D37: ='Monthly Data'!$J$5*(1+Assumptions!$C$35) -> 17 | E37: ='Monthly Data'!$J$5*(1+Assumptions!$C$35) -> 17 | F37: ='Monthly Data'!$J$5*(1+Assumptions!$C$35) -> 17 | G37: ='Monthly Data'!$J$5*(1+Assumptions!$C$35) -> 17 | H37: =H36/H38 -> 17 | I37: Projected CAC held constant due to lack of historical data
A38: Conversions | B38: =B36/B37 -> 5666.6667 | C38: =C36/C37 -> 6000 | D38: =D36/D37 -> 6333.3333 | E38: =E36/E37 -> 7000 | F38: =F36/F37 -> 10000 | G38: =G36/G37 -> 11333.333 | H38: =SUM(B38:G38) -> 46333.333
A39: Revenue ($) | B39: =B38*Assumptions!$B$5 -> 368333.33 | C39: =C38*Assumptions!$B$5 -> 390000 | D39: =D38*Assumptions!$B$5 -> 411666.67 | E39: =E38*Assumptions!$B$5 -> 455000 | F39: =F38*Assumptions!$B$5 -> 650000 | G39: =G38*Assumptions!$B$5 -> 736666.67 | H39: =SUM(B39:G39) -> 3011666.7
A40: Contribution / unit ($) | B40: =Assumptions!$B$9-B37 -> 12.25 | C40: =Assumptions!$B$9-C37 -> 12.25 | D40: =Assumptions!$B$9-D37 -> 12.25 | E40: =Assumptions!$B$9-E37 -> 12.25 | F40: =Assumptions!$B$9-F37 -> 12.25 | G40: =Assumptions!$B$9-G37 -> 12.25
A41: Total contribution ($) | B41: =B40*B38 -> 69416.667 | C41: =C40*C38 -> 73500 | D41: =D40*D38 -> 77583.333 | E41: =E40*E38 -> 85750 | F41: =F40*F38 -> 122500 | G41: =G40*G38 -> 138833.33 | H41: =SUM(B41:G41) -> 567583.33
A43: Blended Total — All Channels
A44: Total spend ($) | B44: =SUM(B9,B18,B27,B36) -> 685251.11 | C44: =SUM(C9,C18,C27,C36) -> 725560 | D44: =SUM(D9,D18,D27,D36) -> 765868.89 | E44: =SUM(E9,E18,E27,E36) -> 846486.67 | F44: =SUM(F9,F18,F27,F36) -> 1209266.7 | G44: =SUM(G9,G18,G27,G36) -> 1370502.2 | H44: =SUM(B44:G44) -> 5602935.6
A45: Total conversions | B45: =SUM(B11,B20,B29,B38) -> 29686.406 | C45: =SUM(C11,C20,C29,C38) -> 31091.087 | D45: =SUM(D11,D20,D29,D38) -> 32512.478 | E45: =SUM(E11,E20,E29,E38) -> 35664.305 | F45: =SUM(F11,F20,F29,F38) -> 50674.41 | G45: =SUM(G11,G20,G29,G38) -> 57272.92 | H45: =SUM(B45:G45) -> 236901.61
A46: Total revenue ($) | B46: =SUM(B12,B21,B30,B39) -> 1929616.4 | C46: =SUM(C12,C21,C30,C39) -> 2020920.7 | D46: =SUM(D12,D21,D30,D39) -> 2113311.1 | E46: =SUM(E12,E21,E30,E39) -> 2318179.8 | F46: =SUM(F12,F21,F30,F39) -> 3293836.6 | G46: =SUM(G12,G21,G30,G39) -> 3722739.8 | H46: =SUM(B46:G46) -> 15398604
...

Sheet Levers & Elasticity
A1: Levers & Elasticity: Spend vs. Conversion Rate
A2: Which lever moves revenue more: a 10% spend increase, or a CVR improvement? Edit the blue inputs on the Assumptions tab to test other sizes.
A4: Baseline — Trailing 6 Months (Jan-Jun 2026)
A5: Total spend ($) | B5: =Assumptions!B12 -> 3950800
A6: Total conversions | B6: =Assumptions!B13 -> 171000
A7: Total clicks | B7: =SUM('Monthly Data'!H2:H5)+SUM('Monthly Data'!H12:H17)+SUM('Monthly Data'!H24:H29)+SUM('Monthly Data'!H36:H41) -> 6573636
A8: Blended CVR | B8: =B6/B7 -> 0.026013001
A9: Total revenue ($) | B9: =Assumptions!B14 -> 11115000
A11: Lever A — Increase Spend by X% (Note: Holds CPC and CVR Constant)
A12: Spend increase % | B12: =Assumptions!B38 -> 0.1
A13: Incremental spend ($) | B13: =B5*B12 -> 395080
A14: New conversions (linear) | B14: =B6*(1+B12) -> 188100
A15: New revenue ($) | B15: =B14*Assumptions!B5 -> 12226500
A16: Revenue lift ($) | B16: =B15-B9 -> 1111500
A17: Implied marginal ROAS on the new dollars | B17: =B16/B13 -> 2.8133543
A18: Naive/linear by design. Real marginal ROAS is almost certainly lower given the worsening CAC trend on Meta and Google. This is really an upper bound.
A20: Lever B1 — Literal Five-Point Blended CVR Shift
A21: Baseline blended CVR | B21: =B8 -> 0.026013001
A22: Literal CVR shift (points) | B22: =Assumptions!B39 -> 0.05
A23: New CVR | B23: =B8+B22 -> 0.076013001
A24: Relative increase in CVR | B24: =B23/B8-1 -> 1.9221158
A25: New conversions | B25: =B7*B23 -> 499681.8
A26: New revenue ($) | B26: =B25*Assumptions!B5 -> 32479317
A27: Revenue lift ($) | B27: =B26-B9 -> 21364317
A28: Taking "five points" literally at the blended level means nearly tripling conversion efficiency overnight, which is not a credible improvement. Flagged red above. Shown only to illustrate why the unit matters.
A30: Lever B2 — Realistic Half-Point (0.5pp) CVR Shift (The Fair Comparison to Lever A)
A31: Realistic CVR shift (points) | B31: =Assumptions!B40 -> 0.005
A32: New CVR | B32: =B8+B31 -> 0.031013001
A33: Relative increase in CVR | B33: =B32/B8-1 -> 0.19221158
A34: New conversions | B34: =B7*B32 -> 203868.18
A35: New revenue ($) | B35: =B34*Assumptions!B5 -> 13251432
A36: Revenue lift ($) | B36: =B35-B9 -> 2136431.7
A38: Head-to-Head: Which Lever Wins?
A39: Lever A revenue lift: +10% spend ($) | B39: =B16 -> 1111500
A40: Lever B2 revenue lift: +0.5pp CVR ($) | B40: =B36 -> 2136431.7
A41: Lever B2 lift as a multiple of Lever A | B41: =B36/B16 -> 1.9221158
A42: A 0.5pp CVR gain delivers roughly 1.92x the revenue of a 10% spend increase, with zero added CAC. CVR work (landing page, checkout, offer) is the higher-impact lever in this scenario.

Sheet Channel Scorecard
A1: Channel Scorecard: June 2026 Snapshot + 12-Month Trend
A2: Spend share vs. contribution share is the real story here, not MER or CAC alone.
A4: Metric | B4: Meta | C4: Google | D4: TikTok | E4: Amazon | F4: Blended Total
A5: June spend ($) | B5: ='Monthly Data'!F29 -> 396800 | C5: ='Monthly Data'!F17 -> 146200 | D5: ='Monthly Data'!F41 -> 53300 | E5: ='Monthly Data'!F5 -> 102000 | F5: =SUM(B5:E5) -> 698300
A6: Spend share of total | B6: =B5/SUM(B5:E5) -> 0.56823715 | C6: =C5/SUM(B5:E5) -> 0.2093656 | D6: =D5/SUM(B5:E5) -> 0.076328226 | E6: =E5/SUM(B5:E5) -> 0.14606902 | F6: =SUM(B6:E6) -> 1
A7: June revenue ($) | B7: ='Monthly Data'!K29 -> 832000 | C7: ='Monthly Data'!K17 -> 559000 | D7: ='Monthly Data'!K41 -> 133250 | E7: ='Monthly Data'!K5 -> 390000 | F7: =SUM(B7:E7) -> 1914250
A8: June MER | B8: ='Monthly Data'!L29 -> 0.47692308 | C8: ='Monthly Data'!L17 -> 0.26153846 | D8: ='Monthly Data'!L41 -> 0.4 | E8: ='Monthly Data'!L5 -> 0.26153846 | F8: =F5/F7 -> 0.36479039
A9: June CVR | B9: ='Monthly Data'!O29 -> 0.018000003 | C9: ='Monthly Data'!O17 -> 0.05 | D9: ='Monthly Data'!O41 -> 0.013999959 | E9: ='Monthly Data'!O5 -> 0.12999957
A10: June CAC ($) | B10: ='Monthly Data'!J29 -> 31 | C10: ='Monthly Data'!J17 -> 17 | D10: ='Monthly Data'!J41 -> 26 | E10: ='Monthly Data'!J5 -> 17 | F10: =F5/F11 -> 23.711375
A11: June conversions | B11: =B5/B10 -> 12800 | C11: =C5/C10 -> 8600 | D11: =D5/D10 -> 2050 | E11: =E5/E10 -> 6000 | F11: =SUM(B11:E11) -> 29450
A12: CAC, first month on record ($) | B12: ='Monthly Data'!J18 -> 22 | C12: ='Monthly Data'!J6 -> 13 | D12: ='Monthly Data'!J30 -> 44 | E12: ='Monthly Data'!J2 -> 22
A13: CAC change, first → last month | B13: =B10/B12-1 -> 0.40909091 | C13: =C10/C12-1 -> 0.30769231 | D13: =D10/D12-1 -> -0.40909091 | E13: =E10/E12-1 -> -0.22727273
A14: Gross profit / unit ($) | B14: =Assumptions!B8 -> 39 | C14: =Assumptions!B8 -> 39 | D14: =Assumptions!B8 -> 39 | E14: =Assumptions!B9 -> 29.25
A15: Contribution / unit, June ($) | B15: =B14-B10 -> 8 | C15: =C14-C10 -> 22 | D15: =D14-D10 -> 13 | E15: =E14-E10 -> 12.25
A16: Total contribution, June ($) | B16: =B15*(B7/Assumptions!$B$5) -> 102400 | C16: =C15*(C7/Assumptions!$B$5) -> 189200 | D16: =D15*(D7/Assumptions!$B$5) -> 26650 | E16: =E15*(E7/Assumptions!$B$5) -> 73500 | F16: =SUM(B16:E16) -> 391750
A17: Share of total June contribution | B17: =B16/SUM(B16:E16) -> 0.26139119 | C17: =C16/SUM(B16:E16) -> 0.48296107 | D17: =D16/SUM(B16:E16) -> 0.068028079 | E17: =E16/SUM(B16:E16) -> 0.18761966 | F17: =SUM(B17:E17) -> 1
A19: Optimize Media Mix (Same Total Budget, Reallocated)
A20: Total spend, held equal to current total ($) | B20: =F5 -> 698300
B21: Meta | C21: Google | D21: TikTok | E21: Amazon | F21: Blended Total
A22: Spend share — EDITABLE | B22: 0.2 | C22: 0.4 | D22: 0.12 | E22: 0.28 | F22: =SUM(B22:E22) -> 1
A23: Spend ($) | B23: =B22*$B$20 -> 139660 | C23: =C22*$B$20 -> 279320 | D23: =D22*$B$20 -> 83796 | E23: =E22*$B$20 -> 195524 | F23: =SUM(B23:E23) -> 698300
A24: June CAC ($) | B24: =B10 -> 31 | C24: =C10 -> 17 | D24: =D10 -> 26 | E24: =E10 -> 17
A25: New conversions | B25: =B23/B24 -> 4505.1613 | C25: =C23/C24 -> 16430.588 | D25: =D23/D24 -> 3222.9231 | E25: =E23/E24 -> 11501.412 | F25: =SUM(B25:E25) -> 35660.084
A26: New revenue ($) | B26: =B25*Assumptions!$B$5 -> 292835.48 | C26: =C25*Assumptions!$B$5 -> 1067988.2 | D26: =D25*Assumptions!$B$5 -> 209490 | E26: =E25*Assumptions!$B$5 -> 747591.76 | F26: =SUM(B26:E26) -> 2317905.5
A27: New total contribution ($) | B27: =B15*B25 -> 36041.29 | C27: =C15*C25 -> 361472.94 | D27: =D15*D25 -> 41898 | E27: =E15*E25 -> 140892.29 | F27: =SUM(B27:E27) -> 580304.53
A28: New share of total contribution | B28: =B27/$F$27 -> 0.062107547 | C28: =C27/$F$27 -> 0.62290216 | D28: =D27/$F$27 -> 0.072200023 | E28: =E27/$F$27 -> 0.24279027 | F28: =SUM(B28:E28) -> 1
A30: Blended MER | F30: =F23/F26 -> 0.30126336
A31: Revenue vs. current (%) | F31: =F26/F7-1 -> 0.21086874
A32: Contribution vs. current (%) | F32: =F27/F16-1 -> 0.4813134
A34: My Recommendation
A35: The underperforming channel is Meta. It represents 57% of total spend but generates only 26% of contribution -- the worst spend-to-contribution ratio in the portfolio, with CAC worsening 41% over the past year. The recommendation is not to pause it (no channel is contribution-negative) but to cut its share from 57% to 20% and redirect that budget toward higher-efficiency channels. Google is the primary destination: 21% of spend but 48% of contribution, and the highest contribution per unit ($22) in the mix. TikTok gets a modest scale test at 12% share, supported by its -41% CAC trend. Amazon absorbs the remainder at 28%, with the caveat that its $17 CAC is misleading without the fee adjustment: contribution per unit is $12.25, roughly half of Google's, because the 15% marketplace fee compresses margin in a way that CAC and MER alone don't surface. Proposed mix: Meta 20%, Google 40%, TikTok 12%, Amazon 28%. Same total budget, +48% contribution, +21% revenue. The strategic call in one sentence: cut Meta, load up on Google where the contribution math is clearest, scale TikTok modestly, and watch Amazon's margin structure closely as spend grows.

Sheet Pressure Test
A1: Pressure Test: 15% Media Inflation Next Quarter
A2: Goal: hold blended MER at or below the ceiling without losing revenue.
A4: Current State — June 2026 Actuals (Pre-Inflation Baseline)
B5: Meta | C5: Google | D5: TikTok | E5: Amazon | F5: Blended Total
A6: Spend ($) | B6: ='Monthly Data'!F29 -> 396800 | C6: ='Monthly Data'!F17 -> 146200 | D6: ='Monthly Data'!F41 -> 53300 | E6: ='Monthly Data'!F5 -> 102000 | F6: =SUM(B6:E6) -> 698300
A7: CAC ($) | B7: ='Monthly Data'!J29 -> 31 | C7: ='Monthly Data'!J17 -> 17 | D7: ='Monthly Data'!J41 -> 26 | E7: ='Monthly Data'!J5 -> 17 | F7: =F6/F8 -> 23.711375
A8: Conversions | B8: =B6/B7 -> 12800 | C8: =C6/C7 -> 8600 | D8: =D6/D7 -> 2050 | E8: =E6/E7 -> 6000 | F8: =SUM(B8:E8) -> 29450
A9: Revenue ($) | B9: ='Monthly Data'!K29 -> 832000 | C9: ='Monthly Data'!K17 -> 559000 | D9: ='Monthly Data'!K41 -> 133250 | E9: ='Monthly Data'!K5 -> 390000 | F9: =SUM(B9:E9) -> 1914250
A10: MER | B10: =B6/B9 -> 0.47692308 | C10: =C6/C9 -> 0.26153846 | D10: =D6/D9 -> 0.4 | E10: =E6/E9 -> 0.26153846 | F10: =F6/F9 -> 0.36479039
A12: Inflation & Target (From Assumptions Tab)
A13: Media inflation, next quarter | B13: =Assumptions!B43 -> 0.15
A14: Target blended MER ceiling | B14: =Assumptions!B44 -> 0.35
A16: Scenario A — Do Nothing (Hold Spend Flat, CAC Increases)
B17: Meta | C17: Google | D17: TikTok | E17: Amazon | F17: Blended Total
A18: Post-inflation CAC ($) | B18: =B7*(1+B13) -> 35.65 | C18: =C7*(1+B13) -> 19.55 | D18: =D7*(1+B13) -> 29.9 | E18: =E7*(1+B13) -> 19.55
A19: Spend ($) [held flat] | B19: =B6 -> 396800 | C19: =C6 -> 146200 | D19: =D6 -> 53300 | E19: =E6 -> 102000 | F19: =SUM(B19:E19) -> 698300
A20: New conversions | B20: =B19/B18 -> 11130.435 | C20: =C19/C18 -> 7478.2609 | D20: =D19/D18 -> 1782.6087 | E20: =E19/E18 -> 5217.3913 | F20: =SUM(B20:E20) -> 25608.696
A21: New revenue ($) | B21: =B20*Assumptions!$B$5 -> 723478.26 | C21: =C20*Assumptions!$B$5 -> 486086.96 | D21: =D20*Assumptions!$B$5 -> 115869.57 | E21: =E20*Assumptions!$B$5 -> 339130.43 | F21: =SUM(B21:E21) -> 1664565.2
A23: Blended MER | F23: =F19/F21 -> 0.41950895
A24: Revenue vs. current (%) | F24: =F21/F9-1 -> -0.13043478
A25: Doing nothing fails on both counts: MER exceeds the ceiling and revenue drops, because inflation hits every channel's CAC equally while spend stays put.
A27: Scenario B — Optimize Media Mix (Same Total Budget, Reallocated)
A28: Total spend, held equal to current total ($) | B28: =F6 -> 698300
B29: Meta | C29: Google | D29: TikTok | E29: Amazon | F29: Blended Total
A30: Spend share — EDITABLE | B30: 0.2 | C30: 0.4 | D30: 0.08 | E30: 0.32 | F30: =SUM(B30:E30) -> 1
A31: Spend ($) | B31: =B30*$B$28 -> 139660 | C31: =C30*$B$28 -> 279320 | D31: =D30*$B$28 -> 55864 | E31: =E30*$B$28 -> 223456 | F31: =SUM(B31:E31) -> 698300
A32: Post-inflation CAC ($) [same as Scenario A] | B32: =B18 -> 35.65 | C32: =C18 -> 19.55 | D32: =D18 -> 29.9 | E32: =E18 -> 19.55
A33: New conversions | B33: =B31/B32 -> 3917.5316 | C33: =C31/C32 -> 14287.468 | D33: =D31/D32 -> 1868.3612 | E33: =E31/E32 -> 11429.974 | F33: =SUM(B33:E33) -> 31503.335
A34: New revenue ($) | B34: =B33*Assumptions!$B$5 -> 254639.55 | C34: =C33*Assumptions!$B$5 -> 928685.42 | D34: =D33*Assumptions!$B$5 -> 121443.48 | E34: =E33*Assumptions!$B$5 -> 742948.34 | F34: =SUM(B34:E34) -> 2047716.8
A36: Spend shares must sum to 100% (flagged red above if not).
A37: Blended MER | F37: =F31/F34 -> 0.34101395
A38: Revenue vs. current (%) | F38: =F34/F9-1 -> 0.069722758
A39: Status | F39: =IF(AND(F37<=B14,F38>=0),"PASS — ceiling held, revenue protected","FAIL — adjust the mix") -> PASS — ceiling held, revenue protected
A41: Real-World Constraints
A42: Google: demand-limited per case notes, so can't absorb unlimited extra budget at the same efficiency; the 40% share above assumes meaningful room to grow but not unlimited room. Worth monitoring CPAs closely as spend increases. Amazon: every extra dollar here still carries the 15% marketplace fee, so shifting budget to Amazon protects MER better than it protects contribution margin. It's important to keep this trade-off in mind. TikTok: held at current share (8%) rather than scaled during an inflation quarter. The improving CAC trend is compelling but untested at higher spend levels, so stacking a scale test on top of a cost-pressure environment adds unnecessary risk. The scaling argument is stronger in a stable quarter. Meta: cutting from 57% to 20% is the most defensible move given the worst trend and worst unit economics in the mix, but it is also the largest channel to unwind quickly without disrupting volume if the reallocation underperforms.

Sheet Monthly Data
A1: Month | B1: Month # | C1: Channel | D1: Season Index | E1: Promo | F1: Spend ($) | G1: Impressions | H1: Clicks | I1: Conversions | J1: CAC ($) | K1: Revenue ($) | L1: MER | M1: ROAS | N1: CTR | O1: CVR | P1: CPC ($) | Q1: CPM ($)
A2: 2026-03 | B2: 9 | C2: Amazon | D2: 1 | F2: 55000 | G2: 5208250 | H2: 20833 | I2: 2500 | J2: =F2/I2 -> 22 | K2: =I2*'Unit Economics & Calendar'!$C$3 -> 162500 | L2: =F2/K2 -> 0.33846154 | M2: =K2/F2 -> 2.9545455 | N2: =H2/G2 -> 0.004 | O2: =I2/H2 -> 0.12000192 | P2: =F2/H2 -> 2.6400422 | Q2: =F2/G2*1000 -> 10.560169
A3: 2026-04 | B3: 10 | C3: Amazon | D3: 0.95 | F3: 76000 | G3: 7916750 | H3: 31667 | I3: 3800 | J3: =F3/I3 -> 20 | K3: =I3*'Unit Economics & Calendar'!$C$3 -> 247000 | L3: =F3/K3 -> 0.30769231 | M3: =K3/F3 -> 3.25 | N3: =H3/G3 -> 0.004 | O3: =I3/H3 -> 0.11999874 | P3: =F3/H3 -> 2.3999747 | Q3: =F3/G3*1000 -> 9.5998989
A4: 2026-05 | B4: 11 | C4: Amazon | D4: 1.05 | E4: Memorial | F4: 93600 | G4: 10000000 | H4: 40000 | I4: 5200 | J4: =F4/I4 -> 18 | K4: =I4*'Unit Economics & Calendar'!$C$3 -> 338000 | L4: =F4/K4 -> 0.27692308 | M4: =K4/F4 -> 3.6111111 | N4: =H4/G4 -> 0.004 | O4: =I4/H4 -> 0.13 | P4: =F4/H4 -> 2.34 | Q4: =F4/G4*1000 -> 9.36
A5: 2026-06 | B5: 12 | C5: Amazon | D5: 0.9 | F5: 102000 | G5: 11538500 | H5: 46154 | I5: 6000 | J5: =F5/I5 -> 17 | K5: =I5*'Unit Economics & Calendar'!$C$3 -> 390000 | L5: =F5/K5 -> 0.26153846 | M5: =K5/F5 -> 3.8235294 | N5: =H5/G5 -> 0.004 | O5: =I5/H5 -> 0.12999957 | P5: =F5/H5 -> 2.2099926 | Q5: =F5/G5*1000 -> 8.8399705
A6: 2025-07 | B6: 1 | C6: Google | D6: 0.85 | F6: 104000 | G6: 3636375 | H6: 145455 | I6: 8000 | J6: =F6/I6 -> 13 | K6: =I6*'Unit Economics & Calendar'!$C$3 -> 520000 | L6: =F6/K6 -> 0.2 | M6: =K6/F6 -> 5 | N6: =H6/G6 -> 0.04 | O6: =I6/H6 -> 0.054999828 | P6: =F6/H6 -> 0.71499777 | Q6: =F6/G6*1000 -> 28.599911
A7: 2025-08 | B7: 2 | C7: Google | D7: 0.9 | F7: 106600 | G7: 3727275 | H7: 149091 | I7: 8200 | J7: =F7/I7 -> 13 | K7: =I7*'Unit Economics & Calendar'!$C$3 -> 533000 | L7: =F7/K7 -> 0.2 | M7: =K7/F7 -> 5 | N7: =H7/G7 -> 0.04 | O7: =I7/H7 -> 0.054999966 | P7: =F7/H7 -> 0.71499956 | Q7: =F7/G7*1000 -> 28.599983
A8: 2025-09 | B8: 3 | C8: Google | D8: 0.95 | F8: 119000 | G8: 3935175 | H8: 157407 | I8: 8500 | J8: =F8/I8 -> 14 | K8: =I8*'Unit Economics & Calendar'!$C$3 -> 552500 | L8: =F8/K8 -> 0.21538462 | M8: =K8/F8 -> 4.6428571 | N8: =H8/G8 -> 0.04 | O8: =I8/H8 -> 0.05400014 | P8: =F8/H8 -> 0.75600196 | Q8: =F8/G8*1000 -> 30.240078
A9: 2025-10 | B9: 4 | C9: Google | D9: 1.05 | F9: 126000 | G9: 4166675 | H9: 166667 | I9: 9000 | J9: =F9/I9 -> 14 | K9: =I9*'Unit Economics & Calendar'!$C$3 -> 585000 | L9: =F9/K9 -> 0.21538462 | M9: =K9/F9 -> 4.6428571 | N9: =H9/G9 -> 0.04 | O9: =I9/H9 -> 0.053999892 | P9: =F9/H9 -> 0.75599849 | Q9: =F9/G9*1000 -> 30.23994
A10: 2025-11 | B10: 5 | C10: Google | D10: 1.5 | E10: BFCM | F10: 138000 | G10: 5133925 | H10: 205357 | I10: 11500 | J10: =F10/I10 -> 12 | K10: =I10*'Unit Economics & Calendar'!$C$3 -> 747500 | L10: =F10/K10 -> 0.18461538 | M10: =K10/F10 -> 5.4166667 | N10: =H10/G10 -> 0.04 | O10: =I10/H10 -> 0.056000039 | P10: =F10/H10 -> 0.67200047 | Q10: =F10/G10*1000 -> 26.880019
A11: 2025-12 | B11: 6 | C11: Google | D11: 1.7 | E11: Holiday | F11: 162500 | G11: 5681825 | H11: 227273 | I11: 12500 | J11: =F11/I11 -> 13 | K11: =I11*'Unit Economics & Calendar'!$C$3 -> 812500 | L11: =F11/K11 -> 0.2 | M11: =K11/F11 -> 5 | N11: =H11/G11 -> 0.04 | O11: =I11/H11 -> 0.054999934 | P11: =F11/H11 -> 0.71499914 | Q11: =F11/G11*1000 -> 28.599966
A12: 2026-01 | B12: 7 | C12: Google | D12: 1.2 | E12: New Year | F12: 147000 | G12: 4952825 | H12: 198113 | I12: 10500 | J12: =F12/I12 -> 14 | K12: =I12*'Unit Economics & Calendar'!$C$3 -> 682500 | L12: =F12/K12 -> 0.21538462 | M12: =K12/F12 -> 4.6428571 | N12: =H12/G12 -> 0.04 | O12: =I12/H12 -> 0.053000056 | P12: =F12/H12 -> 0.74200078 | Q12: =F12/G12*1000 -> 29.680031
A13: 2026-02 | B13: 8 | C13: Google | D13: 1 | F13: 138000 | G13: 4423075 | H13: 176923 | I13: 9200 | J13: =F13/I13 -> 15 | K13: =I13*'Unit Economics & Calendar'!$C$3 -> 598000 | L13: =F13/K13 -> 0.23076923 | M13: =K13/F13 -> 4.3333333 | N13: =H13/G13 -> 0.04 | O13: =I13/H13 -> 0.052000023 | P13: =F13/H13 -> 0.78000034 | Q13: =F13/G13*1000 -> 31.200014
A14: 2026-03 | B14: 9 | C14: Google | D14: 1 | F14: 139500 | G14: 4471150 | H14: 178846 | I14: 9300 | J14: =F14/I14 -> 15 | K14: =I14*'Unit Economics & Calendar'!$C$3 -> 604500 | L14: =F14/K14 -> 0.23076923 | M14: =K14/F14 -> 4.3333333 | N14: =H14/G14 -> 0.04 | O14: =I14/H14 -> 0.052000045 | P14: =F14/H14 -> 0.78000067 | Q14: =F14/G14*1000 -> 31.200027
A15: 2026-04 | B15: 10 | C15: Google | D15: 0.95 | F15: 144000 | G15: 4411775 | H15: 176471 | I15: 9000 | J15: =F15/I15 -> 16 | K15: =I15*'Unit Economics & Calendar'!$C$3 -> 585000 | L15: =F15/K15 -> 0.24615385 | M15: =K15/F15 -> 4.0625 | N15: =H15/G15 -> 0.04 | O15: =I15/H15 -> 0.050999881 | P15: =F15/H15 -> 0.8159981 | Q15: =F15/G15*1000 -> 32.639924
A16: 2026-05 | B16: 11 | C16: Google | D16: 1.05 | E16: Memorial | F16: 144000 | G16: 4615375 | H16: 184615 | I16: 9600 | J16: =F16/I16 -> 15 | K16: =I16*'Unit Economics & Calendar'!$C$3 -> 624000 | L16: =F16/K16 -> 0.23076923 | M16: =K16/F16 -> 4.3333333 | N16: =H16/G16 -> 0.04 | O16: =I16/H16 -> 0.052000108 | P16: =F16/H16 -> 0.78000163 | Q16: =F16/G16*1000 -> 31.200065
A17: 2026-06 | B17: 12 | C17: Google | D17: 0.9 | F17: 146200 | G17: 4300000 | H17: 172000 | I17: 8600 | J17: =F17/I17 -> 17 | K17: =I17*'Unit Economics & Calendar'!$C$3 -> 559000 | L17: =F17/K17 -> 0.26153846 | M17: =K17/F17 -> 3.8235294 | N17: =H17/G17 -> 0.04 | O17: =I17/H17 -> 0.05 | P17: =F17/H17 -> 0.85 | Q17: =F17/G17*1000 -> 34
A18: 2025-07 | B18: 1 | C18: Meta | D18: 0.85 | F18: 264000 | G18: 49586818 | H18: 545455 | I18: 12000 | J18: =F18/I18 -> 22 | K18: =I18*'Unit Economics & Calendar'!$C$3 -> 780000 | L18: =F18/K18 -> 0.33846154 | M18: =K18/F18 -> 2.9545455 | N18: =H18/G18 -> 0.011 | O18: =I18/H18 -> 0.021999982 | P18: =F18/H18 -> 0.4839996 | Q18: =F18/G18*1000 -> 5.3239956
A19: 2025-08 | B19: 2 | C19: Meta | D19: 0.9 | F19: 294400 | G19: 52892545 | H19: 581818 | I19: 12800 | J19: =F19/I19 -> 23 | K19: =I19*'Unit Economics & Calendar'!$C$3 -> 832000 | L19: =F19/K19 -> 0.35384615 | M19: =K19/F19 -> 2.826087 | N19: =H19/G19 -> 0.011 | O19: =I19/H19 -> 0.022000007 | P19: =F19/H19 -> 0.50600016 | Q19: =F19/G19*1000 -> 5.5660018
A20: 2025-09 | B20: 3 | C20: Meta | D20: 0.95 | F20: 324000 | G20: 58441545 | H20: 642857 | I20: 13500 | J20: =F20/I20 -> 24 | K20: =I20*'Unit Economics & Calendar'!$C$3 -> 877500 | L20: =F20/K20 -> 0.36923077 | M20: =K20/F20 -> 2.7083333 | N20: =H20/G20 -> 0.011 | O20: =I20/H20 -> 0.021000005 | P20: =F20/H20 -> 0.50400011 | Q20: =F20/G20*1000 -> 5.5440013
A21: 2025-10 | B21: 4 | C21: Meta | D21: 1.05 | F21: 375000 | G21: 71428600 | H21: 714286 | I21: 15000 | J21: =F21/I21 -> 25 | K21: =I21*'Unit Economics & Calendar'!$C$3 -> 975000 | L21: =F21/K21 -> 0.38461538 | M21: =K21/F21 -> 2.6 | N21: =H21/G21 -> 0.01 | O21: =I21/H21 -> 0.020999992 | P21: =F21/H21 -> 0.52499979 | Q21: =F21/G21*1000 -> 5.2499979
A22: 2025-11 | B22: 5 | C22: Meta | D22: 1.5 | E22: BFCM | F22: 462000 | G22: 86776818 | H22: 954545 | I22: 21000 | J22: =F22/I22 -> 22 | K22: =I22*'Unit Economics & Calendar'!$C$3 -> 1365000 | L22: =F22/K22 -> 0.33846154 | M22: =K22/F22 -> 2.9545455 | N22: =H22/G22 -> 0.011 | O22: =I22/H22 -> 0.02200001 | P22: =F22/H22 -> 0.48400023 | Q22: =F22/G22*1000 -> 5.3240025
A23: 2025-12 | B23: 6 | C23: Meta | D23: 1.7 | E23: Holiday | F23: 552000 | G23: 99173545 | H23: 1090909 | I23: 24000 | J23: =F23/I23 -> 23 | K23: =I23*'Unit Economics & Calendar'!$C$3 -> 1560000 | L23: =F23/K23 -> 0.35384615 | M23: =K23/F23 -> 2.826087 | N23: =H23/G23 -> 0.011 | O23: =I23/H23 -> 0.022000002 | P23: =F23/H23 -> 0.50600004 | Q23: =F23/G23*1000 -> 5.5660005
A24: 2026-01 | B24: 7 | C24: Meta | D24: 1.2 | E24: New Year | F24: 442000 | G24: 85000000 | H24: 850000 | I24: 17000 | J24: =F24/I24 -> 26 | K24: =I24*'Unit Economics & Calendar'!$C$3 -> 1105000 | L24: =F24/K24 -> 0.4 | M24: =K24/F24 -> 2.5 | N24: =H24/G24 -> 0.01 | O24: =I24/H24 -> 0.02 | P24: =F24/H24 -> 0.52 | Q24: =F24/G24*1000 -> 5.2
A25: 2026-02 | B25: 8 | C25: Meta | D25: 1 | F25: 378000 | G25: 70000000 | H25: 700000 | I25: 14000 | J25: =F25/I25 -> 27 | K25: =I25*'Unit Economics & Calendar'!$C$3 -> 910000 | L25: =F25/K25 -> 0.41538462 | M25: =K25/F25 -> 2.4074074 | N25: =H25/G25 -> 0.01 | O25: =I25/H25 -> 0.02 | P25: =F25/H25 -> 0.54 | Q25: =F25/G25*1000 -> 5.4
A26: 2026-03 | B26: 9 | C26: Meta | D26: 1 | F26: 397600 | G26: 74736800 | H26: 747368 | I26: 14200 | J26: =F26/I26 -> 28 | K26: =I26*'Unit Economics & Calendar'!$C$3 -> 923000 | L26: =F26/K26 -> 0.43076923 | M26: =K26/F26 -> 2.3214286 | N26: =H26/G26 -> 0.01 | O26: =I26/H26 -> 0.019000011 | P26: =F26/H26 -> 0.5320003 | Q26: =F26/G26*1000 -> 5.320003
A27: 2026-04 | B27: 10 | C27: Meta | D27: 0.95 | F27: 405000 | G27: 74792211 | H27: 710526 | I27: 13500 | J27: =F27/I27 -> 30 | K27: =I27*'Unit Economics & Calendar'!$C$3 -> 877500 | L27: =F27/K27 -> 0.46153846 | M27: =K27/F27 -> 2.1666667 | N27: =H27/G27 -> 0.0094999999 | O27: =I27/H27 -> 0.019000008 | P27: =F27/H27 -> 0.57000025 | Q27: =F27/G27*1000 -> 5.4150024
A28: 2026-05 | B28: 11 | C28: Meta | D28: 1.05 | E28: Memorial | F28: 429200 | G28: 81994421 | H28: 778947 | I28: 14800 | J28: =F28/I28 -> 29 | K28: =I28*'Unit Economics & Calendar'!$C$3 -> 962000 | L28: =F28/K28 -> 0.44615385 | M28: =K28/F28 -> 2.2413793 | N28: =H28/G28 -> 0.0095 | O28: =I28/H28 -> 0.019000009 | P28: =F28/H28 -> 0.55100026 | Q28: =F28/G28*1000 -> 5.2345025
A29: 2026-06 | B29: 12 | C29: Meta | D29: 0.9 | F29: 396800 | G29: 79012333 | H29: 711111 | I29: 12800 | J29: =F29/I29 -> 31 | K29: =I29*'Unit Economics & Calendar'!$C$3 -> 832000 | L29: =F29/K29 -> 0.47692308 | M29: =K29/F29 -> 2.0967742 | N29: =H29/G29 -> 0.009 | O29: =I29/H29 -> 0.018000003 | P29: =F29/H29 -> 0.55800009 | Q29: =F29/G29*1000 -> 5.0220008
A30: 2025-07 | B30: 1 | C30: TikTok | D30: 0.85 | F30: 39600 | G30: 12500000 | H30: 100000 | I30: 900 | J30: =F30/I30 -> 44 | K30: =I30*'Unit Economics & Calendar'!$C$3 -> 58500 | L30: =F30/K30 -> 0.67692308 | M30: =K30/F30 -> 1.4772727 | N30: =H30/G30 -> 0.008 | O30: =I30/H30 -> 0.009 | P30: =F30/H30 -> 0.396 | Q30: =F30/G30*1000 -> 3.168
A31: 2025-08 | B31: 2 | C31: TikTok | D31: 0.9 | F31: 42000 | G31: 13157875 | H31: 105263 | I31: 1000 | J31: =F31/I31 -> 42 | K31: =I31*'Unit Economics & Calendar'!$C$3 -> 65000 | L31: =F31/K31 -> 0.64615385 | M31: =K31/F31 -> 1.547619 | N31: =H31/G31 -> 0.008 | O31: =I31/H31 -> 0.0095000142 | P31: =F31/H31 -> 0.3990006 | Q31: =F31/G31*1000 -> 3.1920048
A32: 2025-09 | B32: 3 | C32: TikTok | D32: 0.95 | F32: 46000 | G32: 14375000 | H32: 115000 | I32: 1150 | J32: =F32/I32 -> 40 | K32: =I32*'Unit Economics & Calendar'!$C$3 -> 74750 | L32: =F32/K32 -> 0.61538462 | M32: =K32/F32 -> 1.625 | N32: =H32/G32 -> 0.008 | O32: =I32/H32 -> 0.01 | P32: =F32/H32 -> 0.4 | Q32: =F32/G32*1000 -> 3.2
A33: 2025-10 | B33: 4 | C33: TikTok | D33: 1.05 | F33: 49400 | G33: 15476250 | H33: 123810 | I33: 1300 | J33: =F33/I33 -> 38 | K33: =I33*'Unit Economics & Calendar'!$C$3 -> 84500 | L33: =F33/K33 -> 0.58461538 | M33: =K33/F33 -> 1.7105263 | N33: =H33/G33 -> 0.008 | O33: =I33/H33 -> 0.01049996 | P33: =F33/H33 -> 0.39899847 | Q33: =F33/G33*1000 -> 3.1919877
A34: 2025-11 | B34: 5 | C34: TikTok | D34: 1.5 | E34: BFCM | F34: 62700 | G34: 21590875 | H34: 172727 | I34: 1900 | J34: =F34/I34 -> 33 | K34: =I34*'Unit Economics & Calendar'!$C$3 -> 123500 | L34: =F34/K34 -> 0.50769231 | M34: =K34/F34 -> 1.969697 | N34: =H34/G34 -> 0.008 | O34: =I34/H34 -> 0.011000017 | P34: =F34/H34 -> 0.36300057 | Q34: =F34/G34*1000 -> 2.9040046
A35: 2025-12 | B35: 6 | C35: TikTok | D35: 1.7 | E35: Holiday | F35: 73500 | G35: 23863625 | H35: 190909 | I35: 2100 | J35: =F35/I35 -> 35 | K35: =I35*'Unit Economics & Calendar'!$C$3 -> 136500 | L35: =F35/K35 -> 0.53846154 | M35: =K35/F35 -> 1.8571429 | N35: =H35/G35 -> 0.008 | O35: =I35/H35 -> 0.011000005 | P35: =F35/H35 -> 0.38500018 | Q35: =F35/G35*1000 -> 3.0800015
A36: 2026-01 | B36: 7 | C36: TikTok | D36: 1.2 | E36: New Year | F36: 54400 | G36: 17708375 | H36: 141667 | I36: 1700 | J36: =F36/I36 -> 32 | K36: =I36*'Unit Economics & Calendar'!$C$3 -> 110500 | L36: =F36/K36 -> 0.49230769 | M36: =K36/F36 -> 2.03125 | N36: =H36/G36 -> 0.008 | O36: =I36/H36 -> 0.011999972 | P36: =F36/H36 -> 0.3839991 | Q36: =F36/G36*1000 -> 3.0719928
A37: 2026-02 | B37: 8 | C37: TikTok | D37: 1 | F37: 49600 | G37: 16666625 | H37: 133333 | I37: 1600 | J37: =F37/I37 -> 31 | K37: =I37*'Unit Economics & Calendar'!$C$3 -> 104000 | L37: =F37/K37 -> 0.47692308 | M37: =K37/F37 -> 2.0967742 | N37: =H37/G37 -> 0.008 | O37: =I37/H37 -> 0.01200003 | P37: =F37/H37 -> 0.37200093 | Q37: =F37/G37*1000 -> 2.9760074
A38: 2026-03 | B38: 9 | C38: TikTok | D38: 1 | F38: 52500 | G38: 16826875 | H38: 134615 | I38: 1750 | J38: =F38/I38 -> 30 | K38: =I38*'Unit Economics & Calendar'!$C$3 -> 113750 | L38: =F38/K38 -> 0.46153846 | M38: =K38/F38 -> 2.1666667 | N38: =H38/G38 -> 0.008 | O38: =I38/H38 -> 0.013000037 | P38: =F38/H38 -> 0.39000111 | Q38: =F38/G38*1000 -> 3.1200089
A39: 2026-04 | B39: 10 | C39: TikTok | D39: 0.95 | F39: 50400 | G39: 17307750 | H39: 138462 | I39: 1800 | J39: =F39/I39 -> 28 | K39: =I39*'Unit Economics & Calendar'!$C$3 -> 117000 | L39: =F39/K39 -> 0.43076923 | M39: =K39/F39 -> 2.3214286 | N39: =H39/G39 -> 0.008 | O39: =I39/H39 -> 0.012999957 | P39: =F39/H39 -> 0.36399879 | Q39: =F39/G39*1000 -> 2.9119903
A40: 2026-05 | B40: 11 | C40: TikTok | D40: 1.05 | E40: Memorial | F40: 56700 | G40: 19444500 | H40: 155556 | I40: 2100 | J40: =F40/I40 -> 27 | K40: =I40*'Unit Economics & Calendar'!$C$3 -> 136500 | L40: =F40/K40 -> 0.41538462 | M40: =K40/F40 -> 2.4074074 | N40: =H40/G40 -> 0.008 | O40: =I40/H40 -> 0.013499961 | P40: =F40/H40 -> 0.36449896 | Q40: =F40/G40*1000 -> 2.9159917
...

Sheet Blended Summary
A1: Month | B1: Total Spend ($) | C1: Total Conversions | D1: Total Revenue ($) | E1: Blended CAC ($) | F1: Blended MER | G1: Blended ROAS | H1: Season Index | I1: Promo
A2: 2025-07 | B2: =SUMIFS('Monthly Data'!$F:$F,'Monthly Data'!$A:$A,A2) -> 407600 | C2: =SUMIFS('Monthly Data'!$I:$I,'Monthly Data'!$A:$A,A2) -> 20900 | D2: =SUMIFS('Monthly Data'!$K:$K,'Monthly Data'!$A:$A,A2) -> 1358500 | E2: =B2/C2 -> 19.502392 | F2: =B2/D2 -> 0.30003681 | G2: =D2/B2 -> 3.3329244 | H2: 0.85
A3: 2025-08 | B3: =SUMIFS('Monthly Data'!$F:$F,'Monthly Data'!$A:$A,A3) -> 443000 | C3: =SUMIFS('Monthly Data'!$I:$I,'Monthly Data'!$A:$A,A3) -> 22000 | D3: =SUMIFS('Monthly Data'!$K:$K,'Monthly Data'!$A:$A,A3) -> 1430000 | E3: =B3/C3 -> 20.136364 | F3: =B3/D3 -> 0.30979021 | G3: =D3/B3 -> 3.227991 | H3: 0.9
A4: 2025-09 | B4: =SUMIFS('Monthly Data'!$F:$F,'Monthly Data'!$A:$A,A4) -> 489000 | C4: =SUMIFS('Monthly Data'!$I:$I,'Monthly Data'!$A:$A,A4) -> 23150 | D4: =SUMIFS('Monthly Data'!$K:$K,'Monthly Data'!$A:$A,A4) -> 1504750 | E4: =B4/C4 -> 21.12311 | F4: =B4/D4 -> 0.32497093 | G4: =D4/B4 -> 3.0771984 | H4: 0.95
A5: 2025-10 | B5: =SUMIFS('Monthly Data'!$F:$F,'Monthly Data'!$A:$A,A5) -> 550400 | C5: =SUMIFS('Monthly Data'!$I:$I,'Monthly Data'!$A:$A,A5) -> 25300 | D5: =SUMIFS('Monthly Data'!$K:$K,'Monthly Data'!$A:$A,A5) -> 1644500 | E5: =B5/C5 -> 21.754941 | F5: =B5/D5 -> 0.3346914 | G5: =D5/B5 -> 2.987827 | H5: 1.05
A6: 2025-11 | B6: =SUMIFS('Monthly Data'!$F:$F,'Monthly Data'!$A:$A,A6) -> 662700 | C6: =SUMIFS('Monthly Data'!$I:$I,'Monthly Data'!$A:$A,A6) -> 34400 | D6: =SUMIFS('Monthly Data'!$K:$K,'Monthly Data'!$A:$A,A6) -> 2236000 | E6: =B6/C6 -> 19.264535 | F6: =B6/D6 -> 0.29637746 | G6: =D6/B6 -> 3.3740758 | H6: 1.5 | I6: BFCM
A7: 2025-12 | B7: =SUMIFS('Monthly Data'!$F:$F,'Monthly Data'!$A:$A,A7) -> 788000 | C7: =SUMIFS('Monthly Data'!$I:$I,'Monthly Data'!$A:$A,A7) -> 38600 | D7: =SUMIFS('Monthly Data'!$K:$K,'Monthly Data'!$A:$A,A7) -> 2509000 | E7: =B7/C7 -> 20.414508 | F7: =B7/D7 -> 0.31406935 | G7: =D7/B7 -> 3.1840102 | H7: 1.7 | I7: Holiday
A8: 2026-01 | B8: =SUMIFS('Monthly Data'!$F:$F,'Monthly Data'!$A:$A,A8) -> 643400 | C8: =SUMIFS('Monthly Data'!$I:$I,'Monthly Data'!$A:$A,A8) -> 29200 | D8: =SUMIFS('Monthly Data'!$K:$K,'Monthly Data'!$A:$A,A8) -> 1898000 | E8: =B8/C8 -> 22.034247 | F8: =B8/D8 -> 0.33898841 | G8: =D8/B8 -> 2.9499534 | H8: 1.2 | I8: New Year
A9: 2026-02 | B9: =SUMIFS('Monthly Data'!$F:$F,'Monthly Data'!$A:$A,A9) -> 565600 | C9: =SUMIFS('Monthly Data'!$I:$I,'Monthly Data'!$A:$A,A9) -> 24800 | D9: =SUMIFS('Monthly Data'!$K:$K,'Monthly Data'!$A:$A,A9) -> 1612000 | E9: =B9/C9 -> 22.806452 | F9: =B9/D9 -> 0.35086849 | G9: =D9/B9 -> 2.8500707 | H9: 1
A10: 2026-03 | B10: =SUMIFS('Monthly Data'!$F:$F,'Monthly Data'!$A:$A,A10) -> 644600 | C10: =SUMIFS('Monthly Data'!$I:$I,'Monthly Data'!$A:$A,A10) -> 27750 | D10: =SUMIFS('Monthly Data'!$K:$K,'Monthly Data'!$A:$A,A10) -> 1803750 | E10: =B10/C10 -> 23.228829 | F10: =B10/D10 -> 0.3573666 | G10: =D10/B10 -> 2.798247 | H10: 1
A11: 2026-04 | B11: =SUMIFS('Monthly Data'!$F:$F,'Monthly Data'!$A:$A,A11) -> 675400 | C11: =SUMIFS('Monthly Data'!$I:$I,'Monthly Data'!$A:$A,A11) -> 28100 | D11: =SUMIFS('Monthly Data'!$K:$K,'Monthly Data'!$A:$A,A11) -> 1826500 | E11: =B11/C11 -> 24.035587 | F11: =B11/D11 -> 0.36977826 | G11: =D11/B11 -> 2.7043234 | H11: 0.95
A12: 2026-05 | B12: =SUMIFS('Monthly Data'!$F:$F,'Monthly Data'!$A:$A,A12) -> 723500 | C12: =SUMIFS('Monthly Data'!$I:$I,'Monthly Data'!$A:$A,A12) -> 31700 | D12: =SUMIFS('Monthly Data'!$K:$K,'Monthly Data'!$A:$A,A12) -> 2060500 | E12: =B12/C12 -> 22.823344 | F12: =B12/D12 -> 0.35112837 | G12: =D12/B12 -> 2.8479613 | H12: 1.05 | I12: Memorial
A13: 2026-06 | B13: =SUMIFS('Monthly Data'!$F:$F,'Monthly Data'!$A:$A,A13) -> 698300 | C13: =SUMIFS('Monthly Data'!$I:$I,'Monthly Data'!$A:$A,A13) -> 29450 | D13: =SUMIFS('Monthly Data'!$K:$K,'Monthly Data'!$A:$A,A13) -> 1914250 | E13: =B13/C13 -> 23.711375 | F13: =B13/D13 -> 0.36479039 | G13: =D13/B13 -> 2.7413003 | H13: 0.9
A14: TOTAL / Avg | B14: =SUM(B2:B13) -> 7291500 | C14: =SUM(C2:C13) -> 335350 | D14: =SUM(D2:D13) -> 21797750 | E14: =B14/C14 -> 21.742955 | F14: =B14/D14 -> 0.334507 | G14: =D14/B14 -> 2.989474

Sheet Unit Economics & Calendar
B2: Unit Economics and Assumptions
B3: Average order value (AOV) | C3: 65
B4: Gross margin % | C4: 0.6
B5: COGS % (=1 - gross margin) | C5: =1-C4 -> 0.4
B6: Amazon marketplace fee % | C6: 0.15
B7: DTC gross profit per unit | C7: =C3*C4 -> 39
B8: Amazon gross profit per unit | C8: =C3*(C4-C6) -> 29.25
B10: Contribution per unit = gross profit per unit minus channel CAC. Amazon carries the 15% marketplace fee, so its gross profit per unit is lower than DTC even when its CAC looks attractive.
B13: Seasonality and Promo Calendar
B14: Month | C14: Season Index | D14: Promo Event
B15: 2025-07 | C15: 0.85
B16: 2025-08 | C16: 0.9
B17: 2025-09 | C17: 0.95
B18: 2025-10 | C18: 1.05
B19: 2025-11 | C19: 1.5 | D19: Black Friday / Cyber Monday
B20: 2025-12 | C20: 1.7 | D20: Holiday peak
B21: 2026-01 | C21: 1.2 | D21: New Year (resolution demand)
B22: 2026-02 | C22: 1
B23: 2026-03 | C23: 1
B24: 2026-04 | C24: 0.95
B25: 2026-05 | C25: 1.05 | D25: Memorial Day sale
B26: 2026-06 | C26: 0.9
B28: Channel Roles (context)
B29: Meta | C29: Primary prospecting and volume; largest spend; broad audiences.
B30: Google | C30: High-intent capture including brand search; very efficient but demand-limited.
B31: TikTok | C31: Emerging upper-funnel channel; smaller spend; newer to the mix.
B32: Amazon | C32: Marketplace; launched March 2026; subject to a referral fee on revenue.

Sheet Data Dictionary
B2: Data Dictionary
B3: Field | C3: Definition | D3: Formula / Notes
B4: Month | C4: Calendar month | D4: Jul 2025 to Jun 2026
B5: Channel | C5: Paid media channel | D5: Meta, Google, TikTok, Amazon
B6: Season Index | C6: Relative demand vs a 1.00 baseline | D6: Given input
B7: Promo | C7: Promotional event in that month | D7: Given input
B8: Spend | C8: Media spend | D8: Given input
B9: Impressions / Clicks / Conversions | C9: Delivery and orders | D9: Given inputs; last-click attribution
B10: CAC | C10: Customer acquisition cost | D10: Spend / Conversions
B11: Revenue | C11: Channel revenue | D11: Conversions x AOV (AOV constant at $65)
B12: MER | C12: Marketing efficiency ratio | D12: Spend / Revenue; lower is better
B13: ROAS | C13: Return on ad spend | D13: Revenue / Spend
B14: CTR / CVR | C14: Click and conversion rates | D14: Clicks / Impressions ; Conversions / Clicks
... B16: Contribution / unit | C16: Profit after COGS and CAC | D16: Gross profit per unit minus CAC (see Unit Economics)
B18: Note: Revenue uses a constant AOV for simplicity, so it tracks order volume.
